Workbook

Sheet precios_base
A1: PRECIOS BASE — PRODUCTOS LISOS (sin personalización)
A2: Completar celdas amarillas con precio por unidad en pesos. Dejar vacío si no aplica.
A3: producto | B3: variante/detalle | C3: cantidad_min | D3: cantidad_max | E3: precio_unitario_$ | F3: % desc
A4: remera | B4: algodón | C4: 50 | D4: 99 | E4: 13900
A5: remera | B5: algodón | C5: 100 | D5: 199 | E5: 13900
A6: remera | B6: algodón | C6: 200 | D6: 499 | E6: 12900
A7: remera | B7: algodón | C7: 500 | D7: 999 | E7: 12900
A8: remera negra | B8: algodón | C8: 50 | D8: 99 | E8: 13900
A9: remera negra | B9: algodón | C9: 100 | D9: 199 | E9: 13900
A10: remera negra | B10: algodón | C10: 200 | D10: 499 | E10: 12900
A11: remera negra | B11: algodón | C11: 500 | D11: 999 | E11: 12900
A12: remera vintage | B12: algodón | C12: 50 | D12: 99 | E12: 17999
A13: remera vintage | B13: algodón | C13: 100 | D13: 199 | E13: 16999
A14: remera vintage | B14: algodón | C14: 200 | D14: 499 | E14: 15999
A15: remera vintage | B15: algodón | C15: 500 | D15: 999 | E15: 14999
... A19: buzo promocional | B19: algodón total | C19: 500 | D19: 999 | E19: 12999
A20: campera con capucha | C20: 50 | D20: 99 | E20: 19999
A21: campera con capucha | C21: 100 | D21: 199 | E21: 19999
A22: campera con capucha | C22: 200 | D22: 499 | E22: 18999
A23: campera con capucha | C23: 500 | D23: 999 | E23: 17999
A24: gorra | B24: algodón | C24: 50 | D24: 99 | E24: 8999
A25: gorra | B25: algodón | C25: 100 | D25: 199 | E25: 7999
A26: gorra | B26: algodón | C26: 200 | D26: 499 | E26: 7999
A27: gorra | B27: algodón | C27: 500 | D27: 999 | E27: 7999
A28: shopperbag lona | C28: 50 | D28: 99 | E28: 14999
A29: totebag lona | C29: 100 | D29: 199 | E29: 14999
A30: totebag lona | C30: 200 | D30: 499 | E30: 14999
A31: totebag lona | C31: 500 | D31: 999 | E31: 13999
A32: totebag canva beige 40x45 | C32: 50 | D32: 99 | E32: 6999
A33: totebag canva beige 40x45 | C33: 100 | D33: 199 | E33: 6999
A34: totebag canva beige 40x45 | C34: 200 | D34: 499 | E34: 5999
A35: totebag canva beige 40x45 | C35: 500 | D35: 999 | E35: 5999
A36: totebag canva negra 40x45 | C36: 50 | D36: 99 | E36: 7999
A37: totebag canva negra 40x45 | C37: 100 | D37: 199 | E37: 7999
A38: totebag canva negra 40x45 | C38: 200 | D38: 499 | E38: 6999
A39: totebag canva negra 40x45 | C39: 500 | D39: 999 | E39: 6999
... A123: notebook A5 negro 14.2x21.2cm | C123: 500 | D123: 999 | E123: 7990
A124: bolígrafo | C124: 50 | D124: 99
A125: bolígrafo | C125: 100 | D125: 199
A126: bolígrafo | C126: 200 | D126: 299
...

Sheet Copia de precios_base
A1: PRECIOS BASE — PRODUCTOS LISOS (sin personalización)
A2: Completar celdas amarillas con precio por unidad en pesos. Dejar vacío si no aplica.
A3: producto | B3: variante/detalle | C3: cantidad_min | D3: cantidad_max | E3: precio_unitario_$ | F3: % desc
A4: remera | B4: algodón | C4: 50 | D4: 99 | E4: 13900
A5: remera | B5: algodón | C5: 100 | D5: 199 | E5: 13900
A6: remera | B6: algodón | C6: 200 | D6: 499 | E6: 12900
A7: remera | B7: algodón | C7: 500 | D7: 999 | E7: 12900
A8: remera negra | B8: algodón | C8: 50 | D8: 99 | E8: 13900
A9: remera negra | B9: algodón | C9: 100 | D9: 199 | E9: 13900
A10: remera negra | B10: algodón | C10: 200 | D10: 499 | E10: 12900
A11: remera negra | B11: algodón | C11: 500 | D11: 999 | E11: 12900
A12: remera vintage | B12: algodón | C12: 50 | D12: 99 | E12: 17999
A13: remera vintage | B13: algodón | C13: 100 | D13: 199 | E13: 16999
A14: remera vintage | B14: algodón | C14: 200 | D14: 499 | E14: 15999
A15: remera vintage | B15: algodón | C15: 500 | D15: 999 | E15: 14999
... A19: buzo promocional | B19: algodón total | C19: 500 | D19: 999 | E19: 12999
A20: campera con capucha | C20: 50 | D20: 99 | E20: 19999
A21: campera con capucha | C21: 100 | D21: 199 | E21: 19999
A22: campera con capucha | C22: 200 | D22: 499 | E22: 18999
A23: campera con capucha | C23: 500 | D23: 999 | E23: 17999
A24: gorra | B24: algodón | C24: 50 | D24: 99 | E24: 8999
A25: gorra | B25: algodón | C25: 100 | D25: 199 | E25: 7999
A26: gorra | B26: algodón | C26: 200 | D26: 499 | E26: 7999
A27: gorra | B27: algodón | C27: 500 | D27: 999 | E27: 7999
A28: shopperbag lona | C28: 50 | D28: 99 | E28: 14999
A29: totebag lona | C29: 100 | D29: 199 | E29: 14999
A30: totebag lona | C30: 200 | D30: 499 | E30: 14999
A31: totebag lona | C31: 500 | D31: 999 | E31: 13999
A32: totebag canva beige 40x45 | C32: 50 | D32: 99 | E32: 6999
A33: totebag canva beige 40x45 | C33: 100 | D33: 199 | E33: 6999
A34: totebag canva beige 40x45 | C34: 200 | D34: 499 | E34: 5999
A35: totebag canva beige 40x45 | C35: 500 | D35: 999 | E35: 5999
A36: totebag canva negra 40x45 | C36: 50 | D36: 99 | E36: 7999
A37: totebag canva negra 40x45 | C37: 100 | D37: 199 | E37: 7999
A38: totebag canva negra 40x45 | C38: 200 | D38: 499 | E38: 6999
A39: totebag canva negra 40x45 | C39: 500 | D39: 999 | E39: 6999
... A123: notebook A5 negro 14.2x21.2cm | C123: 500 | D123: 999 | E123: 7990
A124: bolígrafo | C124: 50 | D124: 99
A125: bolígrafo | C125: 100 | D125: 199
A126: bolígrafo | C126: 200 | D126: 299
...

Sheet precios_personalizacion
A1: PRECIOS DE PERSONALIZACIÓN — datos del archivo Walter
A2: Celdas amarillas = completar. Celdas con valor = ya cargado del PDF. Este precio se SUMA al precio base.
A3: producto | B3: variante | C3: tecnica | D3: logos / ubicación | E3: colores / diseño / tamaño | F3: cant: 50 | G3: cant: 100 | H3: cant: 200 | I3: cant: 500 | J3: notas
A4: remera | B4: blanca | C4: serigrafia | D4: 1 logo | E4: 1 color | F4: 960 | G4: 850 | H4: 750 | I4: 700
A5: remera | B5: blanca | C5: serigrafia | D5: 1 logo | E5: 2 colores | F5: 1400 | G5: 1360 | H5: 1200 | I5: 1100
A6: remera | B6: blanca | C6: serigrafia | D6: 1 logo | E6: 3 colores | F6: 2200 | G6: 1890 | H6: 1600 | I6: 1450
A7: remera | B7: blanca | C7: serigrafia | D7: 2 logos frente y espalda | E7: 3 colores | F7: 3200 | G7: 2800 | H7: 2600 | I7: 2400
A8: remera | B8: blanca | C8: serigrafia | D8: diseño 30x40 | E8: 3 colores | F8: 3500 | G8: 3000 | H8: 2700 | I8: 2500
A9: remera | B9: blanca | C9: dtf | D9: 1 logo | E9: 1 color | F9: 1200 | G9: 1100 | H9: 900 | I9: 800
A10: remera | B10: blanca | C10: dtf | D10: 1 logo | E10: 2 colores | F10: 1200 | G10: 1100 | H10: 900 | I10: 800
A11: remera | B11: blanca | C11: dtf | D11: 1 logo | E11: full color | F11: 1200 | G11: 1100 | H11: 900 | I11: 800
A12: remera | B12: blanca | C12: dtf | D12: 2 logos frente y espalda | E12: full color | F12: 2200 | G12: 1900 | H12: 1700 | I12: 1500
A13: remera | B13: blanca | C13: dtf | D13: diseño 30x40 | E13: full color | F13: 2000 | G13: 1600 | H13: 1400 | I13: 1300
A14: remera | B14: negra | C14: serigrafia | D14: 1 logo | E14: 1 color | F14: 1300 | G14: 980 | H14: 900 | I14: 840
A15: remera | B15: negra | C15: serigrafia | D15: 1 logo | E15: 2 colores | F15: 2200 | G15: 1600 | H15: 1440 | I15: 1300
A16: remera | B16: negra | C16: serigrafia | D16: 1 logo | E16: 3 colores | F16: 2900 | H16: 1900 | I16: 1750
A17: remera | B17: negra | C17: serigrafia | D17: 2 logos frente y espalda | E17: 3 colores | F17: 3900 | G17: 3150 | H17: 2900 | I17: 2650
A18: remera | B18: negra | C18: serigrafia | D18: diseño 30x40 | E18: 3 colores | F18: 3900 | G18: 3100 | H18: 2900 | I18: 2600
A19: remera | B19: negra | C19: dtf | D19: 1 logo | E19: 1 color | F19: 1200 | G19: 1100 | H19: 900 | I19: 800
A20: remera | B20: negra | C20: dtf | D20: 1 logo | E20: 2 colores | F20: 1200 | G20: 1100 | H20: 900 | I20: 800
A21: remera | B21: negra | C21: dtf | D21: 1 logo | E21: full color | F21: 1200 | G21: 1100 | H21: 900 | I21: 800
A22: remera | B22: negra | C22: dtf | D22: 2 logos frente y espalda | E22: full color | F22: 2400 | G22: 1900 | H22: 1700 | I22: 1500
A23: remera | B23: negra | C23: dtf | D23: diseño 25x35 | E23: full color | F23: 2000 | G23: 1800 | H23: 1600 | I23: 1400
A24: gorra | C24: bordado | D24: 1 logo | F24: =1300*1.21 -> 1573 | G24: =1200*1.21 -> 1452
A25: gorra | C25: bordado | D25: 2 logos | F25: =1900*1.21 -> 2299 | G25: =1800*1.21 -> 2178
A26: gorra | C26: serigrafia | D26: 1 logo | E26: 1 color | F26: 1100 | G26: 980 | H26: 900 | I26: 800
A27: gorra | C27: dtf | D27: 1 logo | E27: 1 color | F27: 1100 | G27: 980 | H27: 800 | I27: 750
A28: piluso | C28: serigrafia | D28: 1 logo | E28: 1 color | F28: 1360 | G28: 980 | H28: 900 | I28: 800
A29: piluso | C29: dtf | D29: 1 logo | E29: 1 color | F29: 1000 | G29: 900 | H29: 800 | I29: 750
A30: piluso | C30: bordado | F30: 1000 | G30: 900
A31: totebag | C31: serigrafia | D31: 1 logo | E31: 1 color | F31: 960 | G31: 850 | H31: 750 | I31: 700
A32: totebag | C32: serigrafia | D32: 1 logo | E32: 2 colores | F32: 1400 | G32: 1360 | H32: 1200 | I32: 1100
A33: totebag | C33: serigrafia | D33: 1 logo | E33: 3 colores o más | F33: 3600 | G33: 3200 | H33: 2900 | I33: 2800
A34: totebag | C34: serigrafia | D34: diseño 25x35 | E34: 3 colores | F34: 2800 | G34: 2800 | H34: 2500 | I34: 2300
A35: totebag | C35: serigrafia | D35: diseño 30x40 | E35: 3 colores | F35: 3100 | G35: 3500 | H35: 3500 | I35: 3200
A36: totebag | C36: dtf | D36: 1 logo | E36: 1 color | F36: 1200 | G36: 1100 | H36: 900 | I36: 800
A37: totebag | C37: dtf | D37: 1 logo | E37: 2 colores | F37: 1200 | G37: 1100 | H37: 900 | I37: 800
A38: totebag | C38: dtf | D38: 1 logo | E38: full color | F38: 1200 | G38: 1100 | H38: 900 | I38: 800
A39: totebag | C39: dtf | D39: 2 logos frente y espalda | E39: full color | F39: 1500 | G39: 1900 | H39: 1700 | I39: 1500
A40: botella/vaso térmico | C40: serigrafia | D40: 1 logo | E40: 1 color | F40: 1000 | G40: 850 | H40: 750 | I40: 700
...

Sheet resumen_precios_finales
A1: RESUMEN PRECIOS FINALES — Base + Personalización (precio unitario en $)
A2: Los precios TOTALES se calculan automáticamente. Verde = precio completo disponible. Amarillo = falta precio base o personalización.
A3: producto | B3: variante | C3: técnica | D3: logos / ubicación | E3: colores / diseño | F3: base 50u | G3: pers. 50u | H3: TOTAL 50u | I3: base 100u | J3: pers. 100u | K3: TOTAL 100u | L3: base 200u | M3: pers. 200u | N3: TOTAL 200u | O3: base 500u | P3: pers. 500u | Q3: TOTAL 500u
A4: remera | B4: blanca | C4: serigrafia | D4: 1 logo | E4: 1 color | F4: =precios_base!E4 -> 13900 | G4: =precios_personalizacion!F14 -> 1300 | H4: =IF(AND(ISNUMBER(precios_base!E4),ISNUMBER(precios_personalizacion!F14)),precios_base!E4+precios_personalizacion!F14,"consultar") -> 15200 | I4: =precios_base!E5 -> 13900 | J4: =precios_personalizacion!G14 -> 980 | K4: =IF(AND(ISNUMBER(precios_base!E5),ISNUMBER(precios_personalizacion!G14)),precios_base!E5+precios_personalizacion!G14,"consultar") -> 14880 | L4: =precios_base!E6 -> 12900 | M4: =precios_personalizacion!H14 -> 900 | N4: =IF(AND(ISNUMBER(precios_base!E6),ISNUMBER(precios_personalizacion!H14)),precios_base!E6+precios_personalizacion!H14,"consultar") -> 13800 | O4: =precios_base!E7 -> 12900 | P4: =precios_personalizacion!I14 -> 840 | Q4: =IF(AND(ISNUMBER(precios_base!E7),ISNUMBER(precios_personalizacion!I14)),precios_base!E7+precios_personalizacion!I14,"consultar") -> 13740
A5: remera | B5: blanca | C5: serigrafia | D5: 1 logo | E5: 2 colores | F5: =precios_base!E4 -> 13900 | G5: =precios_personalizacion!F15 -> 2200 | H5: =IF(AND(ISNUMBER(precios_base!E4),ISNUMBER(precios_personalizacion!F15)),precios_base!E4+precios_personalizacion!F15,"consultar") -> 16100 | I5: =precios_base!E5 -> 13900 | J5: =precios_personalizacion!G15 -> 1600 | K5: =IF(AND(ISNUMBER(precios_base!E5),ISNUMBER(precios_personalizacion!G15)),precios_base!E5+precios_personalizacion!G15,"consultar") -> 15500 | L5: =precios_base!E6 -> 12900 | M5: =precios_personalizacion!H15 -> 1440 | N5: =IF(AND(ISNUMBER(precios_base!E6),ISNUMBER(precios_personalizacion!H15)),precios_base!E6+precios_personalizacion!H15,"consultar") -> 14340 | O5: =precios_base!E7 -> 12900 | P5: =precios_personalizacion!I15 -> 1300 | Q5: =IF(AND(ISNUMBER(precios_base!E7),ISNUMBER(precios_personalizacion!I15)),precios_base!E7+precios_personalizacion!I15,"consultar") -> 14200
A6: remera | B6: blanca | C6: serigrafia | D6: 1 logo | E6: 3 colores | F6: =precios_base!E4 -> 13900 | G6: =precios_personalizacion!F16 -> 2900 | H6: =IF(AND(ISNUMBER(precios_base!E4),ISNUMBER(precios_personalizacion!F16)),precios_base!E4+precios_personalizacion!F16,"consultar") -> 16800 | I6: =precios_base!E5 -> 13900 | J6: =precios_personalizacion!G16 | K6: =IF(AND(ISNUMBER(precios_base!E5),ISNUMBER(precios_personalizacion!G16)),precios_base!E5+precios_personalizacion!G16,"consultar") -> consultar | L6: =precios_base!E6 -> 12900 | M6: =precios_personalizacion!H16 -> 1900 | N6: =IF(AND(ISNUMBER(precios_base!E6),ISNUMBER(precios_personalizacion!H16)),precios_base!E6+precios_personalizacion!H16,"consultar") -> 14800 | O6: =precios_base!E7 -> 12900 | P6: =precios_personalizacion!I16 -> 1750 | Q6: =IF(AND(ISNUMBER(precios_base!E7),ISNUMBER(precios_personalizacion!I16)),precios_base!E7+precios_personalizacion!I16,"consultar") -> 14650
A7: remera | B7: blanca | C7: serigrafia | D7: 2 logos frente y espalda | E7: 3 colores | F7: =precios_base!E4 -> 13900 | G7: =precios_personalizacion!F17 -> 3900 | H7: =IF(AND(ISNUMBER(precios_base!E4),ISNUMBER(precios_personalizacion!F17)),precios_base!E4+precios_personalizacion!F17,"consultar") -> 17800 | I7: =precios_base!E5 -> 13900 | J7: =precios_personalizacion!G17 -> 3150 | K7: =IF(AND(ISNUMBER(precios_base!E5),ISNUMBER(precios_personalizacion!G17)),precios_base!E5+precios_personalizacion!G17,"consultar") -> 17050 | L7: =precios_base!E6 -> 12900 | M7: =precios_personalizacion!H17 -> 2900 | N7: =IF(AND(ISNUMBER(precios_base!E6),ISNUMBER(precios_personalizacion!H17)),precios_base!E6+precios_personalizacion!H17,"consultar") -> 15800 | O7: =precios_base!E7 -> 12900 | P7: =precios_personalizacion!I17 -> 2650 | Q7: =IF(AND(ISNUMBER(precios_base!E7),ISNUMBER(precios_personalizacion!I17)),precios_base!E7+precios_personalizacion!I17,"consultar") -> 15550
A8: remera | B8: blanca | C8: serigrafia | D8: diseño 30x40 | E8: 3 colores | F8: =precios_base!E4 -> 13900 | G8: =precios_personalizacion!F18 -> 3900 | H8: =IF(AND(ISNUMBER(precios_base!E4),ISNUMBER(precios_personalizacion!F18)),precios_base!E4+precios_personalizacion!F18,"consultar") -> 17800 | I8: =precios_base!E5 -> 13900 | J8: =precios_personalizacion!G18 -> 3100 | K8: =IF(AND(ISNUMBER(precios_base!E5),ISNUMBER(precios_personalizacion!G18)),precios_base!E5+precios_personalizacion!G18,"consultar") -> 17000 | L8: =precios_base!E6 -> 12900 | M8: =precios_personalizacion!H18 -> 2900 | N8: =IF(AND(ISNUMBER(precios_base!E6),ISNUMBER(precios_personalizacion!H18)),precios_base!E6+precios_personalizacion!H18,"consultar") -> 15800 | O8: =precios_base!E7 -> 12900 | P8: =precios_personalizacion!I18 -> 2600 | Q8: =IF(AND(ISNUMBER(precios_base!E7),ISNUMBER(precios_personalizacion!I18)),precios_base!E7+precios_personalizacion!I18,"consultar") -> 15500
A9: remera | B9: blanca | C9: dtf | D9: 1 logo | E9: 1 color | F9: =precios_base!E4 -> 13900 | G9: =precios_personalizacion!F19 -> 1200 | H9: =IF(AND(ISNUMBER(precios_base!E4),ISNUMBER(precios_personalizacion!F19)),precios_base!E4+precios_personalizacion!F19,"consultar") -> 15100 | I9: =precios_base!E5 -> 13900 | J9: =precios_personalizacion!G19 -> 1100 | K9: =IF(AND(ISNUMBER(precios_base!E5),ISNUMBER(precios_personalizacion!G19)),precios_base!E5+precios_personalizacion!G19,"consultar") -> 15000 | L9: =precios_base!E6 -> 12900 | M9: =precios_personalizacion!H19 -> 900 | N9: =IF(AND(ISNUMBER(precios_base!E6),ISNUMBER(precios_personalizacion!H19)),precios_base!E6+precios_personalizacion!H19,"consultar") -> 13800 | O9: =precios_base!E7 -> 12900 | P9: =precios_personalizacion!I19 -> 800 | Q9: =IF(AND(ISNUMBER(precios_base!E7),ISNUMBER(precios_personalizacion!I19)),precios_base!E7+precios_personalizacion!I19,"consultar") -> 13700
A10: remera | B10: blanca | C10: dtf | D10: 1 logo | E10: full color | F10: =precios_base!E4 -> 13900 | G10: =precios_personalizacion!F21 -> 1200 | H10: =IF(AND(ISNUMBER(precios_base!E4),ISNUMBER(precios_personalizacion!F21)),precios_base!E4+precios_personalizacion!F21,"consultar") -> 15100 | I10: =precios_base!E5 -> 13900 | J10: =precios_personalizacion!G21 -> 1100 | K10: =IF(AND(ISNUMBER(precios_base!E5),ISNUMBER(precios_personalizacion!G21)),precios_base!E5+precios_personalizacion!G21,"consultar") -> 15000 | L10: =precios_base!E6 -> 12900 | M10: =precios_personalizacion!H21 -> 900 | N10: =IF(AND(ISNUMBER(precios_base!E6),ISNUMBER(precios_personalizacion!H21)),precios_base!E6+precios_personalizacion!H21,"consultar") -> 13800 | O10: =precios_base!E7 -> 12900 | P10: =precios_personalizacion!I21 -> 800 | Q10: =IF(AND(ISNUMBER(precios_base!E7),ISNUMBER(precios_personalizacion!I21)),precios_base!E7+precios_personalizacion!I21,"consultar") -> 13700
A11: remera | B11: blanca | C11: dtf | D11: 2 logos frente y espalda | E11: full color | F11: =precios_base!E4 -> 13900 | G11: =precios_personalizacion!F22 -> 2400 | H11: =IF(AND(ISNUMBER(precios_base!E4),ISNUMBER(precios_personalizacion!F22)),precios_base!E4+precios_personalizacion!F22,"consultar") -> 16300 | I11: =precios_base!E5 -> 13900 | J11: =precios_personalizacion!G22 -> 1900 | K11: =IF(AND(ISNUMBER(precios_base!E5),ISNUMBER(precios_personalizacion!G22)),precios_base!E5+precios_personalizacion!G22,"consultar") -> 15800 | L11: =precios_base!E6 -> 12900 | M11: =precios_personalizacion!H22 -> 1700 | N11: =IF(AND(ISNUMBER(precios_base!E6),ISNUMBER(precios_personalizacion!H22)),precios_base!E6+precios_personalizacion!H22,"consultar") -> 14600 | O11: =precios_base!E7 -> 12900 | P11: =precios_personalizacion!I22 -> 1500 | Q11: =IF(AND(ISNUMBER(precios_base!E7),ISNUMBER(precios_personalizacion!I22)),precios_base!E7+precios_personalizacion!I22,"consultar") -> 14400
A12: remera | B12: blanca | C12: dtf | D12: diseño 30x40 | E12: full color | F12: =precios_base!E4 -> 13900 | G12: =precios_personalizacion!F13 -> 2000 | H12: =IF(AND(ISNUMBER(precios_base!E4),ISNUMBER(precios_personalizacion!F13)),precios_base!E4+precios_personalizacion!F13,"consultar") -> 15900 | I12: =precios_base!E5 -> 13900 | J12: =precios_personalizacion!G13 -> 1600 | K12: =IF(AND(ISNUMBER(precios_base!E5),ISNUMBER(precios_personalizacion!G13)),precios_base!E5+precios_personalizacion!G13,"consultar") -> 15500 | L12: =precios_base!E6 -> 12900 | M12: =precios_personalizacion!H13 -> 1400 | N12: =IF(AND(ISNUMBER(precios_base!E6),ISNUMBER(precios_personalizacion!H13)),precios_base!E6+precios_personalizacion!H13,"consultar") -> 14300 | O12: =precios_base!E7 -> 12900 | P12: =precios_personalizacion!I13 -> 1300 | Q12: =IF(AND(ISNUMBER(precios_base!E7),ISNUMBER(precios_personalizacion!I13)),precios_base!E7+precios_personalizacion!I13,"consultar") -> 14200
A13: remera | B13: negra | C13: serigrafia | D13: 1 logo | E13: 1 color | F13: =precios_base!E4 -> 13900 | G13: =precios_personalizacion!F14 -> 1300 | H13: =IF(AND(ISNUMBER(precios_base!E4),ISNUMBER(precios_personalizacion!F14)),precios_base!E4+precios_personalizacion!F14,"consultar") -> 15200 | I13: =precios_base!E5 -> 13900 | J13: =precios_personalizacion!G14 -> 980 | K13: =IF(AND(ISNUMBER(precios_base!E5),ISNUMBER(precios_personalizacion!G14)),precios_base!E5+precios_personalizacion!G14,"consultar") -> 14880 | L13: =precios_base!E6 -> 12900 | M13: =precios_personalizacion!H14 -> 900 | N13: =IF(AND(ISNUMBER(precios_base!E6),ISNUMBER(precios_personalizacion!H14)),precios_base!E6+precios_personalizacion!H14,"consultar") -> 13800 | O13: =precios_base!E7 -> 12900 | P13: =precios_personalizacion!I14 -> 840 | Q13: =IF(AND(ISNUMBER(precios_base!E7),ISNUMBER(precios_personalizacion!I14)),precios_base!E7+precios_personalizacion!I14,"consultar") -> 13740
A14: remera | B14: negra | C14: serigrafia | D14: 1 logo | E14: 2 colores | F14: =precios_base!E4 -> 13900 | G14: =precios_personalizacion!F15 -> 2200 | H14: =IF(AND(ISNUMBER(precios_base!E4),ISNUMBER(precios_personalizacion!F15)),precios_base!E4+precios_personalizacion!F15,"consultar") -> 16100 | I14: =precios_base!E5 -> 13900 | J14: =precios_personalizacion!G15 -> 1600 | K14: =IF(AND(ISNUMBER(precios_base!E5),ISNUMBER(precios_personalizacion!G15)),precios_base!E5+precios_personalizacion!G15,"consultar") -> 15500 | L14: =precios_base!E6 -> 12900 | M14: =precios_personalizacion!H15 -> 1440 | N14: =IF(AND(ISNUMBER(precios_base!E6),ISNUMBER(precios_personalizacion!H15)),precios_base!E6+precios_personalizacion!H15,"consultar") -> 14340 | O14: =precios_base!E7 -> 12900 | P14: =precios_personalizacion!I15 -> 1300 | Q14: =IF(AND(ISNUMBER(precios_base!E7),ISNUMBER(precios_personalizacion!I15)),precios_base!E7+precios_personalizacion!I15,"consultar") -> 14200
A15: remera | B15: negra | C15: serigrafia | D15: 1 logo | E15: 3 colores | F15: =precios_base!E4 -> 13900 | G15: =precios_personalizacion!F16 -> 2900 | H15: =IF(AND(ISNUMBER(precios_base!E4),ISNUMBER(precios_personalizacion!F16)),precios_base!E4+precios_personalizacion!F16,"consultar") -> 16800 | I15: =precios_base!E5 -> 13900 | J15: =precios_personalizacion!G16 | K15: =IF(AND(ISNUMBER(precios_base!E5),ISNUMBER(precios_personalizacion!G16)),precios_base!E5+precios_personalizacion!G16,"consultar") -> consultar | L15: =precios_base!E6 -> 12900 | M15: =precios_personalizacion!H16 -> 1900 | N15: =IF(AND(ISNUMBER(precios_base!E6),ISNUMBER(precios_personalizacion!H16)),precios_base!E6+precios_personalizacion!H16,"consultar") -> 14800 | O15: =precios_base!E7 -> 12900 | P15: =precios_personalizacion!I16 -> 1750 | Q15: =IF(AND(ISNUMBER(precios_base!E7),ISNUMBER(precios_personalizacion!I16)),precios_base!E7+precios_personalizacion!I16,"consultar") -> 14650
A16: remera | B16: negra | C16: serigrafia | D16: 2 logos frente y espalda | E16: 3 colores | F16: =precios_base!E4 -> 13900 | G16: =precios_personalizacion!F17 -> 3900 | H16: =IF(AND(ISNUMBER(precios_base!E4),ISNUMBER(precios_personalizacion!F17)),precios_base!E4+precios_personalizacion!F17,"consultar") -> 17800 | I16: =precios_base!E5 -> 13900 | J16: =precios_personalizacion!G17 -> 3150 | K16: =IF(AND(ISNUMBER(precios_base!E5),ISNUMBER(precios_personalizacion!G17)),precios_base!E5+precios_personalizacion!G17,"consultar") -> 17050 | L16: =precios_base!E6 -> 12900 | M16: =precios_personalizacion!H17 -> 2900 | N16: =IF(AND(ISNUMBER(precios_base!E6),ISNUMBER(precios_personalizacion!H17)),precios_base!E6+precios_personalizacion!H17,"consultar") -> 15800 | O16: =precios_base!E7 -> 12900 | P16: =precios_personalizacion!I17 -> 2650 | Q16: =IF(AND(ISNUMBER(precios_base!E7),ISNUMBER(precios_personalizacion!I17)),precios_base!E7+precios_personalizacion!I17,"consultar") -> 15550
A17: remera | B17: negra | C17: dtf | D17: 1 logo | E17: 1 color | F17: =precios_base!E4 -> 13900 | G17: =precios_personalizacion!F19 -> 1200 | H17: =IF(AND(ISNUMBER(precios_base!E4),ISNUMBER(precios_personalizacion!F19)),precios_base!E4+precios_personalizacion!F19,"consultar") -> 15100 | I17: =precios_base!E5 -> 13900 | J17: =precios_personalizacion!G19 -> 1100 | K17: =IF(AND(ISNUMBER(precios_base!E5),ISNUMBER(precios_personalizacion!G19)),precios_base!E5+precios_personalizacion!G19,"consultar") -> 15000 | L17: =precios_base!E6 -> 12900 | M17: =precios_personalizacion!H19 -> 900 | N17: =IF(AND(ISNUMBER(precios_base!E6),ISNUMBER(precios_personalizacion!H19)),precios_base!E6+precios_personalizacion!H19,"consultar") -> 13800 | O17: =precios_base!E7 -> 12900 | P17: =precios_personalizacion!I19 -> 800 | Q17: =IF(AND(ISNUMBER(precios_base!E7),ISNUMBER(precios_personalizacion!I19)),precios_base!E7+precios_personalizacion!I19,"consultar") -> 13700
A18: remera | B18: negra | C18: dtf | D18: 1 logo | E18: full color | F18: =precios_base!E4 -> 13900 | G18: =precios_personalizacion!F21 -> 1200 | H18: =IF(AND(ISNUMBER(precios_base!E4),ISNUMBER(precios_personalizacion!F21)),precios_base!E4+precios_personalizacion!F21,"consultar") -> 15100 | I18: =precios_base!E5 -> 13900 | J18: =precios_personalizacion!G21 -> 1100 | K18: =IF(AND(ISNUMBER(precios_base!E5),ISNUMBER(precios_personalizacion!G21)),precios_base!E5+precios_personalizacion!G21,"consultar") -> 15000 | L18: =precios_base!E6 -> 12900 | M18: =precios_personalizacion!H21 -> 900 | N18: =IF(AND(ISNUMBER(precios_base!E6),ISNUMBER(precios_personalizacion!H21)),precios_base!E6+precios_personalizacion!H21,"consultar") -> 13800 | O18: =precios_base!E7 -> 12900 | P18: =precios_personalizacion!I21 -> 800 | Q18: =IF(AND(ISNUMBER(precios_base!E7),ISNUMBER(precios_personalizacion!I21)),precios_base!E7+precios_personalizacion!I21,"consultar") -> 13700
A19: remera | B19: negra | C19: dtf | D19: 2 logos frente y espalda | E19: full color | F19: =precios_base!E4 -> 13900 | G19: =precios_personalizacion!F22 -> 2400 | H19: =IF(AND(ISNUMBER(precios_base!E4),ISNUMBER(precios_personalizacion!F22)),precios_base!E4+precios_personalizacion!F22,"consultar") -> 16300 | I19: =precios_base!E5 -> 13900 | J19: =precios_personalizacion!G22 -> 1900 | K19: =IF(AND(ISNUMBER(precios_base!E5),ISNUMBER(precios_personalizacion!G22)),precios_base!E5+precios_personalizacion!G22,"consultar") -> 15800 | L19: =precios_base!E6 -> 12900 | M19: =precios_personalizacion!H22 -> 1700 | N19: =IF(AND(ISNUMBER(precios_base!E6),ISNUMBER(precios_personalizacion!H22)),precios_base!E6+precios_personalizacion!H22,"consultar") -> 14600 | O19: =precios_base!E7 -> 12900 | P19: =precios_personalizacion!I22 -> 1500 | Q19: =IF(AND(ISNUMBER(precios_base!E7),ISNUMBER(precios_personalizacion!I22)),precios_base!E7+precios_personalizacion!I22,"consultar") -> 14400
A20: remera | B20: negra | C20: dtf | D20: diseño 25x35 | E20: full color | F20: =precios_base!E4 -> 13900 | G20: =precios_personalizacion!F23 -> 2000 | H20: =IF(AND(ISNUMBER(precios_base!E4),ISNUMBER(precios_personalizacion!F23)),precios_base!E4+precios_personalizacion!F23,"consultar") -> 15900 | I20: =precios_base!E5 -> 13900 | J20: =precios_personalizacion!G23 -> 1800 | K20: =IF(AND(ISNUMBER(precios_base!E5),ISNUMBER(precios_personalizacion!G23)),precios_base!E5+precios_personalizacion!G23,"consultar") -> 15700 | L20: =precios_base!E6 -> 12900 | M20: =precios_personalizacion!H23 -> 1600 | N20: =IF(AND(ISNUMBER(precios_base!E6),ISNUMBER(precios_personalizacion!H23)),precios_base!E6+precios_personalizacion!H23,"consultar") -> 14500 | O20: =precios_base!E7 -> 12900 | P20: =precios_personalizacion!I23 -> 1400 | Q20: =IF(AND(ISNUMBER(precios_base!E7),ISNUMBER(precios_personalizacion!I23)),precios_base!E7+precios_personalizacion!I23,"consultar") -> 14300
A21: gorra | C21: serigrafia | D21: 1 logo | E21: 1 color | F21: =precios_base!E24 -> 8999 | G21: =precios_personalizacion!F26 -> 1100 | H21: =IF(AND(ISNUMBER(precios_base!E24),ISNUMBER(precios_personalizacion!F26)),precios_base!E24+precios_personalizacion!F26,"consultar") -> 10099 | I21: =precios_base!E25 -> 7999 | J21: =precios_personalizacion!G26 -> 980 | K21: =IF(AND(ISNUMBER(precios_base!E25),ISNUMBER(precios_personalizacion!G26)),precios_base!E25+precios_personalizacion!G26,"consultar") -> 8979 | L21: =precios_base!E26 -> 7999 | M21: =precios_personalizacion!H26 -> 900 | N21: =IF(AND(ISNUMBER(precios_base!E26),ISNUMBER(precios_personalizacion!H26)),precios_base!E26+precios_personalizacion!H26,"consultar") -> 8899 | O21: =precios_base!E27 -> 7999 | P21: =precios_personalizacion!I26 -> 800 | Q21: =IF(AND(ISNUMBER(precios_base!E27),ISNUMBER(precios_personalizacion!I26)),precios_base!E27+precios_personalizacion!I26,"consultar") -> 8799
A22: gorra | C22: dtf | D22: 1 logo | E22: 1 color | F22: =precios_base!E24 -> 8999 | G22: =precios_personalizacion!F27 -> 1100 | H22: =IF(AND(ISNUMBER(precios_base!E24),ISNUMBER(precios_personalizacion!F27)),precios_base!E24+precios_personalizacion!F27,"consultar") -> 10099 | I22: =precios_base!E25 -> 7999 | J22: =precios_personalizacion!G27 -> 980 | K22: =IF(AND(ISNUMBER(precios_base!E25),ISNUMBER(precios_personalizacion!G27)),precios_base!E25+precios_personalizacion!G27,"consultar") -> 8979 | L22: =precios_base!E26 -> 7999 | M22: =precios_personalizacion!H27 -> 800 | N22: =IF(AND(ISNUMBER(precios_base!E26),ISNUMBER(precios_personalizacion!H27)),precios_base!E26+precios_personalizacion!H27,"consultar") -> 8799 | O22: =precios_base!E27 -> 7999 | P22: =precios_personalizacion!I27 -> 750 | Q22: =IF(AND(ISNUMBER(precios_base!E27),ISNUMBER(precios_personalizacion!I27)),precios_base!E27+precios_personalizacion!I27,"consultar") -> 8749
A23: gorra | C23: bordado | D23: 1 logo | F23: =precios_base!E24 -> 8999 | G23: =precios_personalizacion!F24 -> 1573 | H23: =IF(AND(ISNUMBER(precios_base!E24),ISNUMBER(precios_personalizacion!F24)),precios_base!E24+precios_personalizacion!F24,"consultar") -> 10572 | I23: =precios_base!E25 -> 7999 | J23: =precios_personalizacion!G24 -> 1452 | K23: =IF(AND(ISNUMBER(precios_base!E25),ISNUMBER(precios_personalizacion!G24)),precios_base!E25+precios_personalizacion!G24,"consultar") -> 9451 | L23: =precios_base!E26 -> 7999 | M23: =precios_personalizacion!H24 | N23: =IF(AND(ISNUMBER(precios_base!E26),ISNUMBER(precios_personalizacion!H24)),precios_base!E26+precios_personalizacion!H24,"consultar") -> consultar | O23: =precios_base!E27 -> 7999 | P23: =precios_personalizacion!I24 | Q23: =IF(AND(ISNUMBER(precios_base!E27),ISNUMBER(precios_personalizacion!I24)),precios_base!E27+precios_personalizacion!I24,"consultar") -> consultar
A24: gorra | C24: bordado | D24: 2 logos | F24: =precios_base!E24 -> 8999 | G24: =precios_personalizacion!F25 -> 2299 | H24: =IF(AND(ISNUMBER(precios_base!E24),ISNUMBER(precios_personalizacion!F25)),precios_base!E24+precios_personalizacion!F25,"consultar") -> 11298 | I24: =precios_base!E25 -> 7999 | J24: =precios_personalizacion!G25 -> 2178 | K24: =IF(AND(ISNUMBER(precios_base!E25),ISNUMBER(precios_personalizacion!G25)),precios_base!E25+precios_personalizacion!G25,"consultar") -> 10177 | L24: =precios_base!E26 -> 7999 | M24: =precios_personalizacion!H25 | N24: =IF(AND(ISNUMBER(precios_base!E26),ISNUMBER(precios_personalizacion!H25)),precios_base!E26+precios_personalizacion!H25,"consultar") -> consultar | O24: =precios_base!E27 -> 7999 | P24: =precios_personalizacion!I25 | Q24: =IF(AND(ISNUMBER(precios_base!E27),ISNUMBER(precios_personalizacion!I25)),precios_base!E27+precios_personalizacion!I25,"consultar") -> consultar
A25: piluso | C25: serigrafia | D25: 1 logo | E25: 1 color | F25: =precios_base!E285 -> 5690 | G25: =precios_personalizacion!F28 -> 1360 | H25: =IF(AND(ISNUMBER(precios_base!E285),ISNUMBER(precios_personalizacion!F28)),precios_base!E285+precios_personalizacion!F28,"consultar") -> 7050 | I25: =precios_base!E286 | J25: =precios_personalizacion!G28 -> 980 | K25: =IF(AND(ISNUMBER(precios_base!E286),ISNUMBER(precios_personalizacion!G28)),precios_base!E286+precios_personalizacion!G28,"consultar") -> consultar | L25: =precios_base!E287 | M25: =precios_personalizacion!H28 -> 900 | N25: =IF(AND(ISNUMBER(precios_base!E287),ISNUMBER(precios_personalizacion!H28)),precios_base!E287+precios_personalizacion!H28,"consultar") -> consultar | O25: =precios_base!E288 | P25: =precios_personalizacion!I28 -> 800 | Q25: =IF(AND(ISNUMBER(precios_base!E288),ISNUMBER(precios_personalizacion!I28)),precios_base!E288+precios_personalizacion!I28,"consultar") -> consultar
A26: piluso | C26: dtf | D26: 1 logo | E26: 1 color | F26: =precios_base!E285 -> 5690 | G26: =precios_personalizacion!F29 -> 1000 | H26: =IF(AND(ISNUMBER(precios_base!E285),ISNUMBER(precios_personalizacion!F29)),precios_base!E285+precios_personalizacion!F29,"consultar") -> 6690 | I26: =precios_base!E286 | J26: =precios_personalizacion!G29 -> 900 | K26: =IF(AND(ISNUMBER(precios_base!E286),ISNUMBER(precios_personalizacion!G29)),precios_base!E286+precios_personalizacion!G29,"consultar") -> consultar | L26: =precios_base!E287 | M26: =precios_personalizacion!H29 -> 800 | N26: =IF(AND(ISNUMBER(precios_base!E287),ISNUMBER(precios_personalizacion!H29)),precios_base!E287+precios_personalizacion!H29,"consultar") -> consultar | O26: =precios_base!E288 | P26: =precios_personalizacion!I29 -> 750 | Q26: =IF(AND(ISNUMBER(precios_base!E288),ISNUMBER(precios_personalizacion!I29)),precios_base!E288+precios_personalizacion!I29,"consultar") -> consultar
A27: piluso | C27: bordado | D27: 1 logo | F27: =precios_base!E285 -> 5690 | H27: ="consultar" -> consultar | I27: =precios_base!E286 | K27: ="consultar" -> consultar | L27: =precios_base!E287 | N27: ="consultar" -> consultar | O27: =precios_base!E288 | Q27: ="consultar" -> consultar
A28: totebag | C28: serigrafia | D28: 1 logo | E28: 1 color | G28: =precios_personalizacion!F31 -> 960 | H28: ="consultar" -> consultar | J28: =precios_personalizacion!G31 -> 850 | K28: ="consultar" -> consultar | M28: =precios_personalizacion!H31 -> 750 | N28: ="consultar" -> consultar | P28: =precios_personalizacion!I31 -> 700 | Q28: ="consultar" -> consultar
A29: totebag | C29: serigrafia | D29: 1 logo | E29: 2 colores | G29: =precios_personalizacion!F32 -> 1400 | H29: ="consultar" -> consultar | J29: =precios_personalizacion!G32 -> 1360 | K29: ="consultar" -> consultar | M29: =precios_personalizacion!H32 -> 1200 | N29: ="consultar" -> consultar | P29: =precios_personalizacion!I32 -> 1100 | Q29: ="consultar" -> consultar
A30: totebag | C30: serigrafia | D30: 1 logo | E30: 3 colores o más | G30: =precios_personalizacion!F33 -> 3600 | H30: ="consultar" -> consultar | J30: =precios_personalizacion!G33 -> 3200 | K30: ="consultar" -> consultar | M30: =precios_personalizacion!H33 -> 2900 | N30: ="consultar" -> consultar | P30: =precios_personalizacion!I33 -> 2800 | Q30: ="consultar" -> consultar
A31: totebag | C31: serigrafia | D31: diseño 25x35 | E31: 3 colores | G31: =precios_personalizacion!F34 -> 2800 | H31: ="consultar" -> consultar | J31: =precios_personalizacion!G34 -> 2800 | K31: ="consultar" -> consultar | M31: =precios_personalizacion!H34 -> 2500 | N31: ="consultar" -> consultar | P31: =precios_personalizacion!I34 -> 2300 | Q31: ="consultar" -> consultar
A32: totebag | C32: serigrafia | D32: diseño 30x40 | E32: 3 colores | G32: =precios_personalizacion!F35 -> 3100 | H32: ="consultar" -> consultar | J32: =precios_personalizacion!G35 -> 3500 | K32: ="consultar" -> consultar | M32: =precios_personalizacion!H35 -> 3500 | N32: ="consultar" -> consultar | P32: =precios_personalizacion!I35 -> 3200 | Q32: ="consultar" -> consultar
A33: totebag | C33: dtf | D33: 1 logo | E33: 1 color | G33: =precios_personalizacion!F36 -> 1200 | H33: ="consultar" -> consultar | J33: =precios_personalizacion!G36 -> 1100 | K33: ="consultar" -> consultar | M33: =precios_personalizacion!H36 -> 900 | N33: ="consultar" -> consultar | P33: =precios_personalizacion!I36 -> 800 | Q33: ="consultar" -> consultar
A34: totebag | C34: dtf | D34: 1 logo | E34: full color | G34: =precios_personalizacion!F38 -> 1200 | H34: ="consultar" -> consultar | J34: =precios_personalizacion!G38 -> 1100 | K34: ="consultar" -> consultar | M34: =precios_personalizacion!H38 -> 900 | N34: ="consultar" -> consultar | P34: =precios_personalizacion!I38 -> 800 | Q34: ="consultar" -> consultar
A35: totebag | C35: dtf | D35: 2 logos frente y espalda | E35: full color | G35: =precios_personalizacion!F39 -> 1500 | H35: ="consultar" -> consultar | J35: =precios_personalizacion!G39 -> 1900 | K35: ="consultar" -> consultar | M35: =precios_personalizacion!H39 -> 1700 | N35: ="consultar" -> consultar | P35: =precios_personalizacion!I39 -> 1500 | Q35: ="consultar" -> consultar
A36: botella/vaso térmico | C36: serigrafia | D36: 1 logo | E36: 1 color | G36: =precios_personalizacion!F47 -> 1500 | H36: ="consultar" -> consultar | J36: =precios_personalizacion!G47 -> 1100 | K36: ="consultar" -> consultar | M36: =precios_personalizacion!H47 -> 1050 | N36: ="consultar" -> consultar | P36: =precios_personalizacion!I47 -> 1000 | Q36: ="consultar" -> consultar
A37: botella/vaso térmico | C37: serigrafia | D37: 1 logo | E37: 2 colores | G37: =precios_personalizacion!F41 -> 1400 | H37: ="consultar" -> consultar | J37: =precios_personalizacion!G41 -> 1200 | K37: ="consultar" -> consultar | M37: =precios_personalizacion!H41 | N37: ="consultar" -> consultar | P37: =precios_personalizacion!I41 | Q37: ="consultar" -> consultar
A38: botella/vaso térmico | C38: serigrafia | D38: 2 logos | E38: 1 color | G38: =precios_personalizacion!F48 -> 1800 | H38: ="consultar" -> consultar | J38: =precios_personalizacion!G48 -> 1700 | K38: ="consultar" -> consultar | M38: =precios_personalizacion!H48 -> 1500 | N38: ="consultar" -> consultar | P38: =precios_personalizacion!I48 -> 1400 | Q38: ="consultar" -> consultar
A39: botella/vaso térmico | C39: serigrafia | D39: 360° | E39: full color | G39: =precios_personalizacion!F44 -> 3600 | H39: ="consultar" -> consultar | J39: =precios_personalizacion!G44 -> 3000 | K39: ="consultar" -> consultar | M39: =precios_personalizacion!H44 -> 2800 | N39: ="consultar" -> consultar | P39: =precios_personalizacion!I44 -> 2600 | Q39: ="consultar" -> consultar
A40: botella/vaso térmico | C40: grabado | D40: 1 logo | E40: sin color (grabado) | G40: =precios_personalizacion!F49 -> 1200 | H40: ="consultar" -> consultar | J40: =precios_personalizacion!G49 -> 1100 | K40: ="consultar" -> consultar | M40: =precios_personalizacion!H49 -> 1000 | N40: ="consultar" -> consultar | P40: =precios_personalizacion!I49 -> 900 | Q40: ="consultar" -> consultar
...

Sheet instrucciones_robot
A1: INSTRUCCIONES PARA LA PROGRAMADORA — Configuración del robot de IA
A3: LÓGICA DE PRECIO TOTAL
A4: Precio total por unidad | B4: precio_base (hoja precios_base) + precio_personalizacion (hoja precios_personalizacion)
A5: Sin personalización | B5: Usar solo precio_base. No sumar personalización.
A6: Con personalización | B6: precio_base + precio_personalizacion según combinación exacta
A8: VARIABLES QUE INGRESA EL USUARIO EN LA WEB
A9: 1. producto | B9: remera / buzo / gorra / piluso / totebag / botella / vaso / bolígrafo / llavero / etc.
A10: 2. variante | B10: blanca / negra / plástico / vidrio / metal (según producto)
A11: 3. cantidad | B11: mínimo 50 unidades. Buscar en rango correspondiente.
A12: 4. técnica | B12: serigrafia / dtf / bordado / grabado / laser / tampo / sin personalización
A13: 5. descripción personalización | B13: cantidad de logos / colores / tamaño del diseño según tabla
A15: REGLAS DE NEGOCIO
A16: Cantidad mínima | B16: 50 unidades. Mostrar error si el usuario ingresa menos.
A17: Rangos de cantidad | B17: 50-99 / 100-199 / 200-299 / 500+. Buscar el rango que corresponda.
A18: Precio vacío | B18: Si la celda está vacía (amarilla), mostrar 'consultar precio' al usuario.
A19: Precio total | B19: Mostrar precio unitario Y precio total (unitario × cantidad ingresada).
A20: Nota precio 100 remera negra | B20: El valor $210.000 en el PDF parece un error tipográfico. Verificar con el equipo antes de cargar.
A22: ACTUALIZACIÓN
A23: Cómo actualizar | B23: Modificar celdas amarillas y volver a subir el archivo al sistema.
A24: Frecuencia | B24: Revisar precios 1 vez por mes o ante cambios de proveedor.
